# JavaScript Essentials for React - Part 2: Mastering Error Handling

Welcome to Part 2 of "JavaScript Essentials for React"! In this section, we'll dive deep into a critical aspect of building robust applications: **Error Handling**. How you manage and respond to errors can significantly impact user experience, debugging, and overall application stability. We'll cover standard JavaScript mechanisms and explore patterns inspired by other languages and functional programming paradigms, and specifically how to use Error Boundaries with React Query.

---

## 1. Standard JavaScript Error Handling: `try...catch...finally`

The most fundamental way to handle errors in JavaScript is using the `try...catch...finally` statement.

- **`try` block:** Contains the code that might throw an error.
- **`catch` block:** Executes if an error occurs within the `try` block. It receives an error object (commonly named `error` or `e`) containing details about the error.
- **`finally` block:** Executes after the `try` and `catch` blocks, regardless of whether an error occurred or was caught. It's often used for cleanup operations (e.g., closing files, releasing resources).

**The Error Object:**

When an error is thrown, JavaScript creates an Error object (or an object inheriting from `Error`, like `TypeError`, `SyntaxError`, etc.). Key properties include:

- `name`: The type of error (e.g., "Error", "TypeError").
- `message`: A human-readable description of the error.
- `stack` (non-standard but widely available): A string containing the call stack trace, invaluable for debugging.

**Example:**

```javascript
function parseJsonData(jsonString) {
  try {
    console.log("Attempting to parse JSON...");
    const data = JSON.parse(jsonString);
    console.log("JSON parsed successfully:", data);
    return data;
  } catch (error) {
    // Handle the error
    console.error("Error parsing JSON!");
    console.error("Error Name:", error.name); // e.g., "SyntaxError"
    console.error("Error Message:", error.message); // e.g., "Unexpected token o in JSON at position 1"
    // console.error("Stack Trace:", error.stack); // For debugging
    // You might re-throw the error, throw a custom error, or return a default value
    return null; // Or throw new Error("Failed to parse user data.");
  } finally {
    console.log("JSON parsing attempt finished.");
  }
}

parseJsonData('{"name": "Alice", "age": 30}'); // Success
console.log("---");
parseJsonData('{"name": Bob, "age": 40}'); // Error: Bob is not a string
```

**Best Practices with `try...catch`:**

- **Be specific:** Catch only the errors you expect and know how to handle. Avoid overly broad `catch` blocks that might hide unrelated bugs.
- **Don't swallow errors:** If you catch an error, either handle it meaningfully (e.g., show a user-friendly message, retry), log it for debugging, or re-throw it (or a more specific custom error) if the current scope can't handle it.
- **Use `finally` for cleanup:** Ensure resources are released even if errors occur.

### Common Pitfalls and Considerations with `try...catch`

While `try...catch` is essential, it's important to be aware of potential issues:

**a. Excessive Nesting ("Pyramid of Doom" for Errors):**

Deeply nesting `try...catch` blocks can make code hard to read and maintain, similar to "callback hell."

```javascript
function processUserData(userId) {
  try {
    console.log(`Fetching user ${userId}...`); // Simulate fetch
    if (userId === "errorFetch") throw new Error("Fetch failed");
    const userData = { id: userId, name: "User " + userId };

    try {
      console.log("Processing data for:", userData.name);
      if (userId === "errorProcess") throw new Error("Processing failed");
      const processedData = { ...userData, processed: true };

      try {
        console.log("Saving data for:", processedData.name);
        if (userId === "errorSave") throw new Error("Save failed");
        console.log("User data processed and saved.");
      } catch (saveError) {
        console.error("Error saving data:", saveError.message);
        // Handle save error, maybe rollback previous steps
      }
    } catch (processError) {
      console.error("Error processing data:", processError.message);
      // Handle processing error
    }
  } catch (fetchError) {
    console.error("Error fetching user:", fetchError.message);
    // Handle fetch error
  }
}

// Example calls (uncomment to test)
// processUserData("123");
// processUserData("errorFetch");
// processUserData("errorProcess");
// processUserData("errorSave");
```

**Mitigation:**

- **Break down functions:** Decompose complex operations into smaller functions, each handling its specific errors or throwing them to be caught by a higher-level handler.
- **Promises and `async/await`:** These significantly flatten asynchronous error handling. A single `try...catch` can often handle errors from multiple `await` calls.
- **Centralized error handling:** Use higher-level error handlers or middleware (common in server frameworks or advanced client-side architectures).

**b. `try...catch` with Asynchronous Callbacks (Pre-Promises/`async/await`):**

A `try...catch` block will **not** catch errors thrown in asynchronous callbacks that execute _after_ the `try...catch` block has completed its synchronous execution.

```javascript
function fetchDataWithCallback(callback) {
  console.log("Inside fetchDataWithCallback, scheduling setTimeout...");
  setTimeout(() => {
    console.log("Inside setTimeout callback.");
    // This error happens *after* the outer try...catch has finished
    try {
      const data = JSON.parse("{malformed_json"); // This will throw
      callback(null, data); // Won't be reached if JSON.parse throws
    } catch (e) {
      console.log("Error caught inside setTimeout's try...catch.");
      callback(e, null); // Manually pass error to callback
    }
  }, 100);
  console.log("setTimeout scheduled.");
}

try {
  console.log("Attempting to fetch data with callback...");
  fetchDataWithCallback((error, data) => {
    // The outer try...catch CANNOT catch errors thrown asynchronously inside setTimeout
    // unless the callback itself propagates the error or the async function uses Promises.
    if (error) {
      console.error("Callback received an error:", error.message);
      return;
    }
    console.log("Data from callback:", data);
  });
  console.log("fetchDataWithCallback called, outer try block finished synchronous execution.");
} catch (e) {
  // This catch block will NOT be triggered by an error inside the setTimeout callback
  console.error("Outer catch block (will not run for async error from setTimeout):", e.message);
}
```

**Explanation & Mitigation:**

- The `try...catch` block finishes executing synchronously. The `setTimeout` schedules its callback to run later, outside the scope of that initial `try...catch`.
- **Error-First Callbacks:** The common pattern for older async Node.js-style callbacks is `callback(error, data)`, where the first argument is an error object (or `null` if no error). The callback itself is responsible for checking this error.
- **Promises:** Promises were designed to solve this. A `Promise.catch()` or the `catch` block in an `async/await` structure _can_ catch errors from asynchronous operations within the Promise chain.

**c. Closures and `try...catch` in Asynchronous Operations:**

When using closures with asynchronous operations, ensure that your `catch` block or error handling logic within the closure has access to the correct context or error information.

```javascript
async function processItem(itemId) {
  let attempt = 0;
  const maxAttempts = 3;

  while (attempt < maxAttempts) {
    attempt++;
    try {
      console.log(`Attempt ${attempt} to process item ${itemId}`);
      // Simulate an async operation that might fail
      await new Promise((resolve) => setTimeout(resolve, 50)); // Small delay
      if (itemId === "badId" && attempt < 2) {
        throw new Error("Simulated failure for badId");
      }
      console.log(`Item ${itemId} processed successfully on attempt ${attempt}.`);
      return "Success"; // Exit loop and function on success
    } catch (error) {
      // The 'error' object here is specific to this iteration's try block.
      // 'itemId' and 'attempt' are correctly captured by the closure of this async function's scope.
      console.error(`Attempt ${attempt} for item ${itemId} failed: ${error.message}`);
      if (attempt >= maxAttempts) {
        console.error(`All ${maxAttempts} attempts failed for item ${itemId}.`);
        throw new Error(`Failed to process item ${itemId} after ${maxAttempts} attempts.`);
      }
    }
  }
}

// Example of running the processItem function
// (async () => {
//     try {
//         console.log("--- Processing goodId ---");
//         await processItem("goodId");
//         console.log("--- Processing badId ---");
//         await processItem("badId"); // This will eventually throw after maxAttempts
//     } catch (e) {
//         console.error("Top-level error caught from processItem:", e.message);
//     }
// })();
```

**Key Takeaway:** `async/await` significantly improves handling errors in asynchronous code compared to raw callbacks, making `try...catch` behave more intuitively for sequential asynchronous operations. However, always be mindful of the scope and lifecycle of your error handlers, especially when mixing synchronous and asynchronous logic.

---

## 2. Go-Inspired Error Handling: The `[error, data]` Tuple Pattern

While `try...catch` is powerful, some developers find that it can make asynchronous code harder to follow, especially with many nested calls. A pattern gaining popularity, partly inspired by Go's error handling, involves functions returning a tuple (an array with a fixed number of elements) like `[error, data]`.

**Why this pattern?**

- **Explicit Error Checking:** It forces the caller to explicitly check for an error before using the data.
- **Clearer Control Flow:** The success and error paths are often more explicit in the code.
- **No `try...catch` Proliferation:** You can centralize `try...catch` logic within utility functions and then use the tuple pattern at call sites.
- **Go Inspiration:** In Go, it's idiomatic for functions that can fail to return two values: `(result, error)`. The JavaScript adaptation often uses `[error, result]` so that if `error` is `null`/`undefined`, it's a success.

**The `tryCatch` Utility Function:**

Here's the utility function, which encapsulates this pattern for Promises:

```javascript
async function tryCatchJS(promise) {
  try {
    const data = await promise;
    return [null, data];
  } catch (error) {
    return [error, null];
  }
}
```

**Using the `tryCatch` Utility:**

```javascript
async function fetchDataWithTryCatch(url) {
  const [error, data] = await tryCatchJS(
    fetch(url).then((res) => {
      if (!res.ok) {
        throw new Error(`HTTP error! status: ${res.status} for URL: ${url}`);
      }
      return res.json();
    })
  );

  if (error) {
    console.error(`Failed to fetch data from ${url}:`, error.message);
    return null;
  }

  console.log(`Data fetched successfully from ${url}:`, data);
  return data;
}

// Example usage:
// (async () => {
//     await fetchDataWithTryCatch("https://jsonplaceholder.typicode.com/todos/1");
//     await fetchDataWithTryCatch("https://jsonplaceholder.typicode.com/nonexistent-url");
// })();
```

This pattern makes the error handling path very explicit at the point where `fetchDataWithTryCatch` is called.

---

## 3. Exploring More Advanced Error Handling Patterns

For more complex applications, especially those embracing functional programming principles, developers often turn to dedicated libraries that provide more sophisticated and type-safe ways to handle errors and side effects.

### a. Intermediate: `neverthrow` (Result & Option Types)

**GitHub:** [supermacro/neverthrow](https://github.com/supermacro/neverthrow)

`neverthrow` is a lightweight TypeScript/JavaScript library that provides `Result` and `Option` types, inspired by languages like Rust and Scala.

- **`Result<T, E>` Type:** Represents either a success (`Ok<T>`) containing a value of type `T`, or a failure (`Err<E>`) containing an error of type `E`.
- **`Option<T>` Type:** Represents an optional value – either `Some<T>` (value is present) or `None` (value is absent). Useful for functions that might not return a value, avoiding `null` or `undefined` ambiguity.

**Why use it?**

- **Type Safety (especially with TypeScript):** Makes error states part of the type system, reducing runtime surprises.
- **Explicitness:** Clearly communicates that a function can fail or return no value.
- **Composability:** `Result` and `Option` types often have methods that allow for elegant chaining of operations that might fail.
- **Avoids `null`/`undefined` checks scattered everywhere.**

**Conceptual Example (using `Result`):**

```javascript
// Conceptual plain JS adaptation (for illustration)
const Ok = (value) => ({ _tag: "Ok", value });
const Err = (error) => ({ _tag: "Err", error });

function safeDivide(numerator, denominator) {
  if (denominator === 0) {
    return Err("Cannot divide by zero!");
  }
  return Ok(numerator / denominator);
}

function processResult(result) {
  if (result._tag === "Ok") {
    console.log("Success:", result.value);
  } else {
    console.error("Failure:", result.error);
  }
}

const result1 = safeDivide(10, 2);
processResult(result1);

const result2 = safeDivide(10, 0);
processResult(result2);
```

This approach encourages a more declarative way of handling potential failures.

### b. Advanced: `Effect` (Functional Effect System)

**Website:** [effect.website](https://effect.website/)

**Key Resources:**

- "The Truth About Effect" by Ethan Niser: [ethanniser.dev/blog/the-truth-about-effect/](https://ethanniser.dev/blog/the-truth-about-effect/)
- Error handling by @theo (Video): [youtube.com/watch?v=Y6jT-IkV0VM](https://www.youtube.com/watch?v=Y6jT-IkV0VM)
- Effect-TS Crash Course (Video): [youtube.com/watch?v=Lz2J1NBnHK4](https://www.youtube.com/watch?v=Lz2J1NBnHK4)

`Effect` (often referred to as Effect-TS) is a powerful TypeScript library for building robust, concurrent, and resource-safe applications using a functional programming paradigm. It treats side effects (like network requests, file system access, logging, and even errors) as first-class values called "Effects."

**Core Ideas:**

- **Effects as Values:** Instead of executing side effects immediately, you build up descriptions of these effects.
- **Typed Errors:** Errors are part of an Effect's type signature (`Effect<A, E, R>`).
- **Composition:** Effects can be easily combined, sequenced, and transformed.
- **Concurrency & Resource Management:** Built-in support for managing complex asynchronous operations.
- **Separation of Concerns:** Encourages separating the description of your program's logic from its execution.

**Why consider `Effect`?**

- **Extreme Robustness:** The type system helps eliminate entire classes of runtime errors.
- **Testability:** Effects can be easier to test without actually running the side effects.
- **Scalability for Complex Systems:** It shines in applications with complex asynchronous logic.
- **Comprehensive Ecosystem:** Includes tools for managing state, streams, scheduling, and more.

**Perspective:**

As highlighted in "The Truth About Effect," `Effect` introduces a different way of thinking about program construction. It has a steeper learning curve than traditional approaches but solves deep-seated problems related to side effects and error management that become very apparent in large-scale applications.

```javascript
// Conceptual Effect example (for illustration)
const succeed = (value) => ({ _tag: "Success", value });
const fail = (error) => ({ _tag: "Failure", error });

function program() {
  console.log("Starting Effect program...");
  const value = succeed(42);
  console.log(`Effect got value: ${value.value}`);
  return value.value * 2;
}

// In a real Effect environment, you'd use an Effect runtime to execute this.
const result = program();
console.log("Effect program result:", result);
```

`Effect` provides a very structured and type-safe way to define computations that can succeed or fail.

**Conclusion for Part 2:**

Effective error handling is non-negotiable for quality software. Starting with `try...catch...finally`, understanding its nuances and common pitfalls, exploring patterns like the `[error, data]` tuple, being aware of more advanced libraries like `neverthrow` and `Effect`
